<?xml version="1.0" ?>
<!-- =================================================================================== -->
<!-- |    This document was autogenerated by xacro from irb6400r.xacro                 | -->
<!-- |    EDITING THIS FILE BY HAND IS NOT RECOMMENDED                                 | -->
<!-- =================================================================================== -->
<robot name="abb_irb6400r">
  <!-- link list -->
  <link name="base_link">
    <collision name="collision">
      <geometry>
        <convex_mesh convert="true" filename="package://wire_cutting/meshes/irb6400r/collision/base_link.stl"/>
      </geometry>
      <material name="yellow">
        <color rgba="0 1 1 1"/>
      </material>
    </collision>
    <visual name="visual">
      <geometry>
        <mesh filename="package://wire_cutting/meshes/irb6400r/visual/base_link.stl"/>
      </geometry>
      <material name="orange">
        <color rgba="1 0.43 0 1"/>
      </material>
    </visual>
  </link>
  <link name="link_1">
    <collision name="collision">
      <geometry>
        <convex_mesh convert="true" filename="package://wire_cutting/meshes/irb6400r/collision/link_1.stl"/>
      </geometry>
      <material name="yellow"/>
    </collision>
    <visual name="visual">
      <geometry>
        <mesh filename="package://wire_cutting/meshes/irb6400r/visual/link_1.stl"/>
      </geometry>
      <material name="orange"/>
    </visual>
  </link>
  <link name="link_2">
    <collision name="collision">
      <geometry>
        <convex_mesh convert="true" filename="package://wire_cutting/meshes/irb6400r/collision/link_2.stl"/>
      </geometry>
      <material name="yellow"/>
    </collision>
    <visual name="visual">
      <geometry>
        <mesh filename="package://wire_cutting/meshes/irb6400r/visual/link_2.stl"/>
      </geometry>
      <material name="orange"/>
    </visual>
  </link>
  <link name="link_3">
    <collision name="collision">
      <geometry>
        <convex_mesh convert="true" filename="package://wire_cutting/meshes/irb6400r/collision/link_3.stl"/>
      </geometry>
      <material name="yellow"/>
    </collision>
    <visual name="visual">
      <geometry>
        <mesh filename="package://wire_cutting/meshes/irb6400r/visual/link_3.stl"/>
      </geometry>
      <material name="orange"/>
    </visual>
  </link>
  <link name="link_4">
    <collision name="collision">
      <geometry>
        <convex_mesh convert="true" filename="package://wire_cutting/meshes/irb6400r/collision/link_4.stl"/>
      </geometry>
      <material name="yellow"/>
    </collision>
    <visual name="visual">
      <geometry>
        <mesh filename="package://wire_cutting/meshes/irb6400r/visual/link_4.stl"/>
      </geometry>
      <material name="orange"/>
    </visual>
  </link>
  <link name="link_5">
    <collision name="collision">
      <geometry>
        <convex_mesh convert="true" filename="package://wire_cutting/meshes/irb6400r/collision/link_5.stl"/>
      </geometry>
      <material name="yellow"/>
    </collision>
    <visual name="visual">
      <geometry>
        <mesh filename="package://wire_cutting/meshes/irb6400r/visual/link_5.stl"/>
      </geometry>
      <material name="orange"/>
    </visual>
  </link>
  <link name="link_6">
    <collision name="collision">
      <geometry>
        <convex_mesh convert="true" filename="package://wire_cutting/meshes/irb6400r/collision/link_6.stl"/>
      </geometry>
      <material name="yellow"/>
    </collision>
    <visual name="visual">
      <geometry>
        <mesh filename="package://wire_cutting/meshes/irb6400r/visual/link_6.stl"/>
      </geometry>
      <material name="orange"/>
    </visual>
  </link>
  <link name="tool0"/>
  <!--Cylinder and piston -->
  <!--link name="${prefix}link_cylinder">
      <collision name="collision">
        <geometry>
          <mesh filename="package://wire_cutting/meshes/irb6400r/collision/cylinder.stl"/>
        </geometry>
        <material name="yellow"/>
      </collision>
      <visual name="visual">
        <geometry>
          <mesh filename="package://wire_cutting/meshes/irb6400r/visual/cylinder.stl"/>
        </geometry>
        <material name="orange"/>
      </visual>
    </link>
    <link name="${prefix}link_piston">
      <collision name="collision">
        <geometry>
          <mesh filename="package://wire_cutting/meshes/irb6400r/collision/piston.stl"/>
        </geometry>
        <material name="yellow"/>
      </collision>
      <visual name="visual">
        <geometry>
          <mesh filename="package://wire_cutting/meshes/irb6400r/visual/piston.stl"/>
        </geometry>
        <material name="orange"/>
      </visual>
    </link> -->
  <!-- end of link list -->
  <!-- joint list -->
  <!-- TODO update limits and velocities (bar linkage between axis 2 and 3!)-->
  <joint name="joint_1" type="revolute">
    <origin rpy="0 0 0" xyz="0 0 0.27"/>
    <axis xyz="0 0 1"/>
    <parent link="base_link"/>
    <child link="link_1"/>
    <limit effort="0" lower="-2.967" upper="2.967" velocity="1.7453"/>
  </joint>
  <joint name="joint_2" type="revolute">
    <origin rpy="0 0 0" xyz="0.240 0. 0.53"/>
    <axis xyz="0 1 0"/>
    <parent link="link_1"/>
    <child link="link_2"/>
    <limit effort="0" lower="-1.134" upper="1.4855" velocity="1.5707"/>
  </joint>
  <!-- TODO fix 3rd axis geometry -->
  <joint name="joint_3" type="revolute">
    <origin rpy="0 0 0" xyz="0 0 1.05"/>
    <axis xyz="0 1 0"/>
    <parent link="link_2"/>
    <child link="link_3"/>
    <limit effort="0" lower="-3.142" upper="1.222" velocity="1.5707"/>
  </joint>
  <!-- TODO find isue with 4-5 axis joint position -->
  <joint name="joint_4" type="revolute">
    <origin rpy="0 0 0" xyz="0 0 0.225"/>
    <axis xyz="1 0 0"/>
    <parent link="link_3"/>
    <child link="link_4"/>
    <limit effort="0" lower="-5.236" upper="5.236" velocity="2.9671"/>
  </joint>
  <joint name="joint_5" type="revolute">
    <origin rpy="0 0 0" xyz="1.485 0 0 "/>
    <axis xyz="0 1 0"/>
    <parent link="link_4"/>
    <child link="link_5"/>
    <limit effort="0" lower="-2.094" upper="2.094" velocity="2.4435"/>
  </joint>
  <!-- TODO verify 0.145! -->
  <joint name="joint_6" type="revolute">
    <origin rpy="0 0 0" xyz="0.145 0 0 "/>
    <axis xyz="1 0 0"/>
    <parent link="link_5"/>
    <child link="link_6"/>
    <limit effort="0" lower="-6.283" upper="6.283" velocity="3.3161"/>
  </joint>
  <joint name="joint_6-tool0" type="fixed">
    <parent link="link_6"/>
    <child link="tool0"/>
    <origin rpy="0 1.57079632679 0" xyz=".037 0 0"/>
  </joint>
  <!--<joint type="fixed" name="${prefix}joint_cylinder">
      <origin xyz="-0.365 -0.1895 0.405" rpy="0 -0.170 0"/>
      <axis xyz="0 1 0"/>
      <parent link="${prefix}link_1"/>
      <child link="${prefix}link_cylinder"/>
      <limit effort="0" lower="-2.96705973" upper="2.96705973" velocity="0"/>
    </joint>
    <joint type="fixed" name="${prefix}joint_piston">
      <origin xyz="0.475 0 0" rpy="0 0 0"/>
      <axis xyz="1 0 0"/>
      <parent link="${prefix}link_cylinder"/>
      <child link="${prefix}link_piston"/>
      <limit effort="0" lower="0" upper="0.6" velocity="0"/>
    </joint>-->
  <!-- end of joint list -->
  <!-- ROS base_link to ABB World Coordinates transform -->
  <link name="base"/>
  <joint name="base_link-base" type="fixed">
    <origin rpy="0 0 0" xyz="0 0 0"/>
    <parent link="base_link"/>
    <child link="base"/>
  </joint>
</robot>

