<?xml version="1.0"?>
<robot xmlns:xacro="http://ros.org/wiki/xacro">
  
  <xacro:macro name="irb6400r" params="prefix">
    <!-- link list -->
    <link name="${prefix}base_link">
      <collision name="collision">
        <geometry>
          <convex_mesh filename="package://wire_cutting/meshes/irb6400r/collision/base_link.stl" convert="true"/>
        </geometry>
        <material name="yellow">
          <color rgba="0 1 1 1"/>
        </material>
      </collision>
      <visual name="visual">
        <geometry>
          <mesh filename="package://wire_cutting/meshes/irb6400r/visual/base_link.stl"/>
        </geometry>
        <material name="orange">
          <color rgba="1 0.43 0 1"/>
        </material>
      </visual>
    </link>
    <link name="${prefix}link_1">
      <collision name="collision">
        <geometry>
          <convex_mesh filename="package://wire_cutting/meshes/irb6400r/collision/link_1.stl" convert="true"/>
        </geometry>
        <material name="yellow"/>
      </collision>
      <visual name="visual">
        <geometry>
          <mesh filename="package://wire_cutting/meshes/irb6400r/visual/link_1.stl"/>
        </geometry>
        <material name="orange"/>
      </visual>
    </link>
    <link name="${prefix}link_2">
      <collision name="collision">
        <geometry>
          <convex_mesh filename="package://wire_cutting/meshes/irb6400r/collision/link_2.stl" convert="true"/>
        </geometry>
        <material name="yellow"/>
      </collision>
      <visual name="visual">
        <geometry>
          <mesh filename="package://wire_cutting/meshes/irb6400r/visual/link_2.stl"/>
        </geometry>
        <material name="orange"/>
      </visual>
    </link>
    <link name="${prefix}link_3">
      <collision name="collision">
        <geometry>
          <convex_mesh filename="package://wire_cutting/meshes/irb6400r/collision/link_3.stl" convert="true"/>
        </geometry>
        <material name="yellow"/>
      </collision>
      <visual name="visual">
        <geometry>
          <mesh filename="package://wire_cutting/meshes/irb6400r/visual/link_3.stl"/>
        </geometry>
        <material name="orange"/>
      </visual>
    </link>
    <link name="${prefix}link_4">
      <collision name="collision">
        <geometry>
          <convex_mesh filename="package://wire_cutting/meshes/irb6400r/collision/link_4.stl" convert="true"/>
        </geometry>
        <material name="yellow"/>
      </collision>
      <visual name="visual">
        <geometry>
          <mesh filename="package://wire_cutting/meshes/irb6400r/visual/link_4.stl"/>
        </geometry>
        <material name="orange"/>
      </visual>
    </link>
    <link name="${prefix}link_5">
      <collision name="collision">
        <geometry>
          <convex_mesh filename="package://wire_cutting/meshes/irb6400r/collision/link_5.stl" convert="true"/>
        </geometry>
        <material name="yellow"/>
      </collision>
      <visual name="visual">
        <geometry>
          <mesh filename="package://wire_cutting/meshes/irb6400r/visual/link_5.stl"/>
        </geometry>
        <material name="orange"/>
      </visual>
    </link>
    <link name="${prefix}link_6">
      <collision name="collision">
        <geometry>
          <convex_mesh filename="package://wire_cutting/meshes/irb6400r/collision/link_6.stl" convert="true"/>
        </geometry>
        <material name="yellow"/>
      </collision>
      <visual name="visual">
        <geometry>
          <mesh filename="package://wire_cutting/meshes/irb6400r/visual/link_6.stl"/>
        </geometry>
        <material name="orange"/>
      </visual>
    </link>
    <link name="${prefix}tool0"/>
    
    <link name="${prefix}carbon_hotwire" >
      <visual>
        <geometry>
          <mesh filename="package://wire_cutting/meshes/carbon_hotwire.stl" />
        </geometry>>
      </visual>
      <collision>
        <geometry>
          <mesh filename="package://wire_cutting/meshes/carbon_hotwire.stl" />
        </geometry>
      </collision>
    </link>
    
    <!--Cylinder and piston -->
    <!--link name="${prefix}link_cylinder">
      <collision name="collision">
        <geometry>
          <mesh filename="package://wire_cutting/meshes/irb6400r/collision/cylinder.stl"/>
        </geometry>
        <material name="yellow"/>
      </collision>
      <visual name="visual">
        <geometry>
          <mesh filename="package://wire_cutting/meshes/irb6400r/visual/cylinder.stl"/>
        </geometry>
        <material name="orange"/>
      </visual>
    </link>
    <link name="${prefix}link_piston">
      <collision name="collision">
        <geometry>
          <mesh filename="package://wire_cutting/meshes/irb6400r/collision/piston.stl"/>
        </geometry>
        <material name="yellow"/>
      </collision>
      <visual name="visual">
        <geometry>
          <mesh filename="package://wire_cutting/meshes/irb6400r/visual/piston.stl"/>
        </geometry>
        <material name="orange"/>
      </visual>
    </link> -->
    <!-- end of link list --> 
    
    <!-- joint list -->
    <!-- TODO update limits and velocities (bar linkage between axis 2 and 3!)-->
    <joint type="revolute" name="${prefix}joint_1">
      <origin xyz="0 0 0.27" rpy="0 0 0"/>
      <axis xyz="0 0 1"/>
      <parent link="${prefix}base_link"/>
      <child link="${prefix}link_1"/>
      <limit effort="0" lower="-3.14" upper="3.14" velocity="1.57"/>
    </joint>
    <joint type="revolute" name="${prefix}joint_2">
      <origin xyz="0.240 0. 0.53" rpy="0 0 0"/>
      <axis xyz="0 1 0"/>
      <parent link="${prefix}link_1"/>
      <child link="${prefix}link_2"/>
      <limit effort="0" lower="-1.22" upper="1.48" velocity="1.22"/>
    </joint>
    <!-- TODO fix 3rd axis geometry -->
    <joint type="revolute" name="${prefix}joint_3">
      <origin xyz="0 0 1.05" rpy="0 0 0"/>
      <axis xyz="0 1 0"/>
      <parent link="${prefix}link_2"/>
      <child link="${prefix}link_3"/>
      <limit effort="0" lower="-0.489" upper="1.92" velocity="1.22"/>
    </joint>
    <!-- TODO find isue with 4-5 axis joint position -->
    <joint type="revolute" name="${prefix}joint_4">
      <origin xyz="0 0 0.225" rpy="0 0 0"/>
      <axis xyz="1 0 0"/>
      <parent link="${prefix}link_3"/>
      <child link="${prefix}link_4"/>
      <limit effort="0" lower="-5.23" upper="5.23" velocity="1.91"/>
    </joint>
    <joint type="revolute" name="${prefix}joint_5">
      <origin xyz="1.725 0 0 " rpy="0 0 0"/>
      <axis xyz="0 1 0"/>
      <parent link="${prefix}link_4"/>
      <child link="${prefix}link_5"/>
      <limit effort="0" lower="-2.094" upper="2.094" velocity="1.91"/>
    </joint>
     <!-- TODO verify 0.145! -->
    <joint type="revolute" name="${prefix}joint_6">
      <origin xyz="0.145 0 0 " rpy="0 0 0"/>
      <axis xyz="1 0 0"/>
      <parent link="${prefix}link_5"/>
      <child link="${prefix}link_6"/>
      <limit effort="0" lower="-5.23" upper="5.23" velocity="1.91"/>
    </joint>
    <joint type="fixed" name="${prefix}joint_6-tool0">
      <parent link="${prefix}link_6"/>
      <child link="${prefix}tool0"/>
      <origin xyz=".037 0 0" rpy="0 1.57079632679 0"/>
    </joint>
    <joint type="fixed" name="${prefix}tool0-carbon_hotwire">
      <parent link="${prefix}tool0"/>
      <child link="${prefix}carbon_hotwire"/>
      <origin xyz="0 0 1.861" rpy="0 0 0"/>
    </joint>
    
    
    <!--<joint type="fixed" name="${prefix}joint_cylinder">
      <origin xyz="-0.365 -0.1895 0.405" rpy="0 -0.170 0"/>
      <axis xyz="0 1 0"/>
      <parent link="${prefix}link_1"/>
      <child link="${prefix}link_cylinder"/>
      <limit effort="0" lower="-2.96705973" upper="2.96705973" velocity="0"/>
    </joint>
    <joint type="fixed" name="${prefix}joint_piston">
      <origin xyz="0.475 0 0" rpy="0 0 0"/>
      <axis xyz="1 0 0"/>
      <parent link="${prefix}link_cylinder"/>
      <child link="${prefix}link_piston"/>
      <limit effort="0" lower="0" upper="0.6" velocity="0"/>
    </joint>-->
    <!-- end of joint list -->
    
    <!-- ROS base_link to ABB World Coordinates transform -->
    <link name="${prefix}base" />
    <joint name="${prefix}base_link-base" type="fixed">
      <origin xyz="0 0 0" rpy="0 0 0"/>
      <parent link="${prefix}base_link"/>
      <child link="${prefix}base"/>
    </joint>
  </xacro:macro>
</robot>
