<?xml version="1.0" encoding="utf-8"?>
<!-- =================================================================================== -->
<!-- |    This document was autogenerated by xacro from /home/jonathan/projects/wirecutting_ws/src/wire_cutting_mp/wire_cutting/urdf/wire_cutting_workcell.xacro | -->
<!-- |    EDITING THIS FILE BY HAND IS NOT RECOMMENDED                                 | -->
<!-- =================================================================================== -->
<robot name="irb6400r">
  <!-- link list -->
  <link name="base_link">
    <collision name="collision">
      <geometry>
        <convex_mesh convert="true" filename="package://wire_cutting/meshes/irb6400r/collision/base_link.stl"/>
      </geometry>
      <material name="yellow">
        <color rgba="0 1 1 1"/>
      </material>
    </collision>
    <visual name="visual">
      <geometry>
        <mesh filename="package://wire_cutting/meshes/irb6400r/visual/base_link.stl"/>
      </geometry>
      <material name="orange">
        <color rgba="1 0.43 0 1"/>
      </material>
    </visual>
  </link>
  <link name="link_1">
    <collision name="collision">
      <geometry>
        <convex_mesh convert="true" filename="package://wire_cutting/meshes/irb6400r/collision/link_1.stl"/>
      </geometry>
      <material name="yellow"/>
    </collision>
    <visual name="visual">
      <geometry>
        <mesh filename="package://wire_cutting/meshes/irb6400r/visual/link_1.stl"/>
      </geometry>
      <material name="orange"/>
    </visual>
  </link>
  <link name="link_2">
    <collision name="collision">
      <geometry>
        <convex_mesh convert="true" filename="package://wire_cutting/meshes/irb6400r/collision/link_2.stl"/>
      </geometry>
      <material name="yellow"/>
    </collision>
    <visual name="visual">
      <geometry>
        <mesh filename="package://wire_cutting/meshes/irb6400r/visual/link_2.stl"/>
      </geometry>
      <material name="orange"/>
    </visual>
  </link>
  <link name="link_3">
    <collision name="collision">
      <geometry>
        <convex_mesh convert="true" filename="package://wire_cutting/meshes/irb6400r/collision/link_3.stl"/>
      </geometry>
      <material name="yellow"/>
    </collision>
    <visual name="visual">
      <geometry>
        <mesh filename="package://wire_cutting/meshes/irb6400r/visual/link_3.stl"/>
      </geometry>
      <material name="orange"/>
    </visual>
  </link>
  <link name="link_4">
    <collision name="collision">
      <geometry>
        <convex_mesh convert="true" filename="package://wire_cutting/meshes/irb6400r/collision/link_4.stl"/>
      </geometry>
      <material name="yellow"/>
    </collision>
    <visual name="visual">
      <geometry>
        <mesh filename="package://wire_cutting/meshes/irb6400r/visual/link_4.stl"/>
      </geometry>
      <material name="orange"/>
    </visual>
  </link>
  <link name="link_5">
    <collision name="collision">
      <geometry>
        <convex_mesh convert="true" filename="package://wire_cutting/meshes/irb6400r/collision/link_5.stl"/>
      </geometry>
      <material name="yellow"/>
    </collision>
    <visual name="visual">
      <geometry>
        <mesh filename="package://wire_cutting/meshes/irb6400r/visual/link_5.stl"/>
      </geometry>
      <material name="orange"/>
    </visual>
  </link>
  <link name="link_6">
    <collision name="collision">
      <geometry>
        <convex_mesh convert="true" filename="package://wire_cutting/meshes/irb6400r/collision/link_6.stl"/>
      </geometry>
      <material name="yellow"/>
    </collision>
    <visual name="visual">
      <geometry>
        <mesh filename="package://wire_cutting/meshes/irb6400r/visual/link_6.stl"/>
      </geometry>
      <material name="orange"/>
    </visual>
  </link>
  <link name="tool0"/>
  <!--<link name="${prefix}carbon_hotwire" >
      <collision>
        <geometry>
          <convex_mesh filename="package://wire_cutting/meshes/carbon_hotwire.stl" />
        </geometry>
        <material name="yellow"/>
      </collision>
      <visual>
        <geometry>
          <mesh filename="package://wire_cutting/meshes/carbon_hotwire.stl" />
        </geometry>>
      </visual>
    </link>-->
  <joint name="joint_1" type="revolute">
    <origin rpy="0 0 0" xyz="0 0 0.27"/>
    <axis xyz="0 0 1"/>
    <parent link="base_link"/>
    <child link="link_1"/>
    <limit effort="0" lower="-3.14" upper="3.14" velocity="1.57"/>
  </joint>
  <joint name="joint_2" type="revolute">
    <origin rpy="0 0 0" xyz="0.240 0. 0.53"/>
    <axis xyz="0 1 0"/>
    <parent link="link_1"/>
    <child link="link_2"/>
    <limit effort="0" lower="-1.22" upper="1.48" velocity="1.22"/>
  </joint>
  <joint name="joint_3" type="revolute">
    <origin rpy="0 0 0" xyz="0 0 1.05"/>
    <axis xyz="0 1 0"/>
    <parent link="link_2"/>
    <child link="link_3"/>
    <limit effort="0" lower="-3.14" upper="3.14" velocity="1.22"/>
    <!-- Limits defined by constraints due to parallel link-->
  </joint>
  <joint name="joint_4" type="revolute">
    <origin rpy="0 0 0" xyz="0.0 0 0.225"/>
    <axis xyz="1 0 0"/>
    <parent link="link_3"/>
    <child link="link_4"/>
    <limit effort="0" lower="-5.23" upper="5.23" velocity="1.91"/>
  </joint>
  <joint name="joint_5" type="revolute">
    <origin rpy="0 0 0" xyz="1.725 0 0 "/>
    <axis xyz="0 1 0"/>
    <parent link="link_4"/>
    <child link="link_5"/>
    <limit effort="0" lower="-2.094" upper="2.094" velocity="1.91"/>
  </joint>
  <!-- TODO verify 0.145! -->
  <joint name="joint_6" type="revolute">
    <origin rpy="0 0 0" xyz="0.145 0 0 "/>
    <axis xyz="1 0 0"/>
    <parent link="link_5"/>
    <child link="link_6"/>
    <limit effort="0" lower="-5.23" upper="5.23" velocity="1.91"/>
  </joint>
  <joint name="joint_6-tool0" type="fixed">
    <parent link="link_6"/>
    <child link="tool0"/>
    <origin rpy="0 1.57079632679 0" xyz=".037 0 0"/>
  </joint>
  <!--<joint type="fixed" name="${prefix}tool0-carbon_hotwire">
      <parent link="${prefix}tool0"/>
      <child link="${prefix}carbon_hotwire"/>
      <origin xyz="0 0 1.861" rpy="0 0 0"/>
    </joint>-->
  <!-- ROS base_link to ABB World Coordinates transform -->
  <link name="base"/>
  <joint name="base_link-base" type="fixed">
    <origin rpy="0 0 0" xyz="0 0 0"/>
    <parent link="base_link"/>
    <child link="base"/>
  </joint>
  <link name="carbon_hotwire_mount"/>
  <link name="carbon_hotwire">
    <collision>
      <geometry>
        <convex_mesh convert="true" filename="package://wire_cutting/meshes/CH_top.stl"/>
      </geometry>
      <material name="yellow"/>
    </collision>
    <visual>
      <geometry>
        <mesh filename="package://wire_cutting/meshes/CH_top.stl"/>
      </geometry>
      &gt;
      <material name="grey">
        <color rgba="0.5 0.5 0.5 1"/>
      </material>
    </visual>
  </link>
  <joint name="mount" type="fixed">
    <parent link="carbon_hotwire_mount"/>
    <child link="carbon_hotwire"/>
    <origin rpy="0 0 0" xyz="0 0 1.861"/>
  </joint>
  <link name="CH_left">
    <collision>
      <geometry>
        <convex_mesh convert="true" filename="package://wire_cutting/meshes/CH_left.stl"/>
      </geometry>
    </collision>
    <visual>
      <material name="grey"/>
      <geometry>
        <mesh filename="package://wire_cutting/meshes/CH_left.stl"/>
      </geometry>
      &gt;
      
    </visual>
  </link>
  <link name="CH_right">
    <collision>
      <geometry>
        <convex_mesh convert="true" filename="package://wire_cutting/meshes/CH_right.stl"/>
      </geometry>
      <material name="yellow"/>
    </collision>
    <visual>
    <material name="grey"/>
      <geometry>
        <mesh filename="package://wire_cutting/meshes/CH_right.stl"/>
      </geometry>
      &gt;
      
    </visual>
  </link>
  <joint name="top-left" type="fixed">
    <parent link="carbon_hotwire"/>
    <child link="CH_left"/>
    <origin rpy="0 0 0" xyz="0 0 0"/>
  </joint>
  <joint name="top-right" type="fixed">
    <parent link="carbon_hotwire"/>
    <child link="CH_right"/>
    <origin rpy="0 0 0" xyz="0 0 0"/>
  </joint>
  <joint name="tool" type="fixed">
    <parent link="tool0"/>
    <child link="carbon_hotwire_mount"/>
    <origin rpy="0 0 3.14" xyz="0 0 0"/>
  </joint>
</robot>
